[2024-05-31T17:00:00.735+0000] {local_task_job_runner.py:120} INFO - ::group::Pre task execution logs
[2024-05-31T17:00:00.758+0000] {taskinstance.py:2076} INFO - Dependencies all met for dep_context=non-requeueable deps ti=<TaskInstance: etl_process.get_all_users manual__2024-05-31T16:59:59.519125+00:00 [queued]>
[2024-05-31T17:00:00.769+0000] {taskinstance.py:2076} INFO - Dependencies all met for dep_context=requeueable deps ti=<TaskInstance: etl_process.get_all_users manual__2024-05-31T16:59:59.519125+00:00 [queued]>
[2024-05-31T17:00:00.769+0000] {taskinstance.py:2306} INFO - Starting attempt 1 of 2
[2024-05-31T17:00:00.787+0000] {taskinstance.py:2330} INFO - Executing <Task(_PythonDecoratedOperator): get_all_users> on 2024-05-31 16:59:59.519125+00:00
[2024-05-31T17:00:00.809+0000] {warnings.py:110} WARNING - /home/***/.local/lib/python3.12/site-packages/***/task/task_runner/standard_task_runner.py:61: DeprecationWarning: This process (pid=1350) is multi-threaded, use of fork() may lead to deadlocks in the child.
  pid = os.fork()

[2024-05-31T17:00:00.807+0000] {standard_task_runner.py:90} INFO - Running: ['***', 'tasks', 'run', 'etl_process', 'get_all_users', 'manual__2024-05-31T16:59:59.519125+00:00', '--job-id', '3144', '--raw', '--subdir', 'DAGS_FOLDER/etl_process.py', '--cfg-path', '/tmp/tmpvv_47mmp']
[2024-05-31T17:00:00.817+0000] {standard_task_runner.py:91} INFO - Job 3144: Subtask get_all_users
[2024-05-31T17:00:00.817+0000] {standard_task_runner.py:63} INFO - Started process 1352 to run task
[2024-05-31T17:00:00.856+0000] {warnings.py:110} WARNING - /home/***/.local/lib/python3.12/site-packages/***/settings.py:195: DeprecationWarning: The sql_alchemy_conn option in [core] has been moved to the sql_alchemy_conn option in [database] - the old setting has been used, but please update your config.
  SQL_ALCHEMY_CONN = conf.get("database", "SQL_ALCHEMY_CONN")

[2024-05-31T17:00:00.990+0000] {task_command.py:426} INFO - Running <TaskInstance: etl_process.get_all_users manual__2024-05-31T16:59:59.519125+00:00 [running]> on host 94d98bd81efc
[2024-05-31T17:00:01.134+0000] {taskinstance.py:2648} INFO - Exporting env vars: AIRFLOW_CTX_DAG_EMAIL='anhnguyen@westcliff.edu' AIRFLOW_CTX_DAG_OWNER='Anh' AIRFLOW_CTX_DAG_ID='etl_process' AIRFLOW_CTX_TASK_ID='get_all_users' AIRFLOW_CTX_EXECUTION_DATE='2024-05-31T16:59:59.519125+00:00' AIRFLOW_CTX_TRY_NUMBER='1' AIRFLOW_CTX_DAG_RUN_ID='manual__2024-05-31T16:59:59.519125+00:00'
[2024-05-31T17:00:01.135+0000] {taskinstance.py:430} INFO - ::endgroup::
[2024-05-31T17:00:01.153+0000] {taskinstance.py:441} INFO - ::group::Post task execution logs
[2024-05-31T17:00:01.153+0000] {taskinstance.py:2905} ERROR - Task failed with exception
Traceback (most recent call last):
  File "/home/airflow/.local/lib/python3.12/site-packages/airflow/models/taskinstance.py", line 465, in _execute_task
    result = _execute_callable(context=context, **execute_callable_kwargs)
             ^^^^^^^^^^^^^^^^^^^^^^^^^^^^^^^^^^^^^^^^^^^^^^^^^^^^^^^^^^^^^
  File "/home/airflow/.local/lib/python3.12/site-packages/airflow/models/taskinstance.py", line 432, in _execute_callable
    return execute_callable(context=context, **execute_callable_kwargs)
           ^^^^^^^^^^^^^^^^^^^^^^^^^^^^^^^^^^^^^^^^^^^^^^^^^^^^^^^^^^^^
  File "/home/airflow/.local/lib/python3.12/site-packages/airflow/models/baseoperator.py", line 400, in wrapper
    return func(self, *args, **kwargs)
           ^^^^^^^^^^^^^^^^^^^^^^^^^^^
  File "/home/airflow/.local/lib/python3.12/site-packages/airflow/decorators/base.py", line 265, in execute
    return_value = super().execute(context)
                   ^^^^^^^^^^^^^^^^^^^^^^^^
  File "/home/airflow/.local/lib/python3.12/site-packages/airflow/models/baseoperator.py", line 400, in wrapper
    return func(self, *args, **kwargs)
           ^^^^^^^^^^^^^^^^^^^^^^^^^^^
  File "/home/airflow/.local/lib/python3.12/site-packages/airflow/operators/python.py", line 235, in execute
    return_value = self.execute_callable()
                   ^^^^^^^^^^^^^^^^^^^^^^^
  File "/home/airflow/.local/lib/python3.12/site-packages/airflow/operators/python.py", line 252, in execute_callable
    return self.python_callable(*self.op_args, **self.op_kwargs)
           ^^^^^^^^^^^^^^^^^^^^^^^^^^^^^^^^^^^^^^^^^^^^^^^^^^^^^
  File "/opt/airflow/dags/etl_process.py", line 42, in get_all_users
    header = {'Authorization' : 'Bearer ' + myToken}
                                ~~~~~~~~~~^~~~~~~~~
TypeError: can only concatenate str (not "NoneType") to str
[2024-05-31T17:00:01.166+0000] {taskinstance.py:1206} INFO - Marking task as UP_FOR_RETRY. dag_id=etl_process, task_id=get_all_users, run_id=manual__2024-05-31T16:59:59.519125+00:00, execution_date=20240531T165959, start_date=20240531T170000, end_date=20240531T170001
[2024-05-31T17:00:01.180+0000] {standard_task_runner.py:110} ERROR - Failed to execute job 3144 for task get_all_users (can only concatenate str (not "NoneType") to str; 1352)
[2024-05-31T17:00:01.197+0000] {local_task_job_runner.py:240} INFO - Task exited with return code 1
[2024-05-31T17:00:01.226+0000] {taskinstance.py:3498} INFO - 0 downstream tasks scheduled from follow-on schedule check
[2024-05-31T17:00:01.228+0000] {local_task_job_runner.py:222} INFO - ::endgroup::
