[2024-05-31T17:20:04.840+0000] {local_task_job_runner.py:120} INFO - ::group::Pre task execution logs
[2024-05-31T17:20:04.869+0000] {taskinstance.py:2076} INFO - Dependencies all met for dep_context=non-requeueable deps ti=<TaskInstance: etl_process.get_all_users manual__2024-05-31T17:20:03.718523+00:00 [queued]>
[2024-05-31T17:20:04.879+0000] {taskinstance.py:2076} INFO - Dependencies all met for dep_context=requeueable deps ti=<TaskInstance: etl_process.get_all_users manual__2024-05-31T17:20:03.718523+00:00 [queued]>
[2024-05-31T17:20:04.879+0000] {taskinstance.py:2306} INFO - Starting attempt 1 of 2
[2024-05-31T17:20:04.893+0000] {taskinstance.py:2330} INFO - Executing <Task(_PythonDecoratedOperator): get_all_users> on 2024-05-31 17:20:03.718523+00:00
[2024-05-31T17:20:04.899+0000] {warnings.py:110} WARNING - /home/***/.local/lib/python3.12/site-packages/***/task/task_runner/standard_task_runner.py:61: DeprecationWarning: This process (pid=1992) is multi-threaded, use of fork() may lead to deadlocks in the child.
  pid = os.fork()

[2024-05-31T17:20:04.900+0000] {standard_task_runner.py:63} INFO - Started process 1993 to run task
[2024-05-31T17:20:04.900+0000] {standard_task_runner.py:90} INFO - Running: ['***', 'tasks', 'run', 'etl_process', 'get_all_users', 'manual__2024-05-31T17:20:03.718523+00:00', '--job-id', '3146', '--raw', '--subdir', 'DAGS_FOLDER/etl_process.py', '--cfg-path', '/tmp/tmpfyzlixgx']
[2024-05-31T17:20:04.901+0000] {standard_task_runner.py:91} INFO - Job 3146: Subtask get_all_users
[2024-05-31T17:20:04.915+0000] {warnings.py:110} WARNING - /home/***/.local/lib/python3.12/site-packages/***/settings.py:195: DeprecationWarning: The sql_alchemy_conn option in [core] has been moved to the sql_alchemy_conn option in [database] - the old setting has been used, but please update your config.
  SQL_ALCHEMY_CONN = conf.get("database", "SQL_ALCHEMY_CONN")

[2024-05-31T17:20:04.955+0000] {task_command.py:426} INFO - Running <TaskInstance: etl_process.get_all_users manual__2024-05-31T17:20:03.718523+00:00 [running]> on host 94d98bd81efc
[2024-05-31T17:20:05.049+0000] {taskinstance.py:2648} INFO - Exporting env vars: AIRFLOW_CTX_DAG_EMAIL='anhnguyen@westcliff.edu' AIRFLOW_CTX_DAG_OWNER='Anh' AIRFLOW_CTX_DAG_ID='etl_process' AIRFLOW_CTX_TASK_ID='get_all_users' AIRFLOW_CTX_EXECUTION_DATE='2024-05-31T17:20:03.718523+00:00' AIRFLOW_CTX_TRY_NUMBER='1' AIRFLOW_CTX_DAG_RUN_ID='manual__2024-05-31T17:20:03.718523+00:00'
[2024-05-31T17:20:05.050+0000] {taskinstance.py:430} INFO - ::endgroup::
[2024-05-31T17:20:05.051+0000] {etl_process.py:35} INFO - get_all_users
[2024-05-31T17:20:05.067+0000] {taskinstance.py:441} INFO - ::group::Post task execution logs
[2024-05-31T17:20:05.068+0000] {taskinstance.py:2905} ERROR - Task failed with exception
Traceback (most recent call last):
  File "/home/airflow/.local/lib/python3.12/site-packages/airflow/models/taskinstance.py", line 465, in _execute_task
    result = _execute_callable(context=context, **execute_callable_kwargs)
             ^^^^^^^^^^^^^^^^^^^^^^^^^^^^^^^^^^^^^^^^^^^^^^^^^^^^^^^^^^^^^
  File "/home/airflow/.local/lib/python3.12/site-packages/airflow/models/taskinstance.py", line 432, in _execute_callable
    return execute_callable(context=context, **execute_callable_kwargs)
           ^^^^^^^^^^^^^^^^^^^^^^^^^^^^^^^^^^^^^^^^^^^^^^^^^^^^^^^^^^^^
  File "/home/airflow/.local/lib/python3.12/site-packages/airflow/models/baseoperator.py", line 400, in wrapper
    return func(self, *args, **kwargs)
           ^^^^^^^^^^^^^^^^^^^^^^^^^^^
  File "/home/airflow/.local/lib/python3.12/site-packages/airflow/decorators/base.py", line 265, in execute
    return_value = super().execute(context)
                   ^^^^^^^^^^^^^^^^^^^^^^^^
  File "/home/airflow/.local/lib/python3.12/site-packages/airflow/models/baseoperator.py", line 400, in wrapper
    return func(self, *args, **kwargs)
           ^^^^^^^^^^^^^^^^^^^^^^^^^^^
  File "/home/airflow/.local/lib/python3.12/site-packages/airflow/operators/python.py", line 235, in execute
    return_value = self.execute_callable()
                   ^^^^^^^^^^^^^^^^^^^^^^^
  File "/home/airflow/.local/lib/python3.12/site-packages/airflow/operators/python.py", line 252, in execute_callable
    return self.python_callable(*self.op_args, **self.op_kwargs)
           ^^^^^^^^^^^^^^^^^^^^^^^^^^^^^^^^^^^^^^^^^^^^^^^^^^^^^
  File "/opt/airflow/dags/etl_process.py", line 43, in get_all_users
    header = {'Authorization' : 'Bearer ' + myToken}
                                ~~~~~~~~~~^~~~~~~~~
TypeError: can only concatenate str (not "NoneType") to str
[2024-05-31T17:20:05.080+0000] {taskinstance.py:1206} INFO - Marking task as UP_FOR_RETRY. dag_id=etl_process, task_id=get_all_users, run_id=manual__2024-05-31T17:20:03.718523+00:00, execution_date=20240531T172003, start_date=20240531T172004, end_date=20240531T172005
[2024-05-31T17:20:05.093+0000] {standard_task_runner.py:110} ERROR - Failed to execute job 3146 for task get_all_users (can only concatenate str (not "NoneType") to str; 1993)
[2024-05-31T17:20:05.115+0000] {local_task_job_runner.py:240} INFO - Task exited with return code 1
[2024-05-31T17:20:05.142+0000] {taskinstance.py:3498} INFO - 0 downstream tasks scheduled from follow-on schedule check
[2024-05-31T17:20:05.144+0000] {local_task_job_runner.py:222} INFO - ::endgroup::
